오류란 무엇인가요?
컴파일 오류 :
실행 오류 :

시스템 오류(error) : 가상 머신에서 발생, 프로그래머가 처리 할 수 없음, 동적 메모리가 없는 경우, 스택 오버 플로우 등
예외(exception): 파일이 존재하지 않는 경우, 네트웍 연결이 끊긴 경우

대국민 서비스는 네트웍 연결이 끊긴다면 (만약 메신저가 끊긴다면) 해결방안을 장애 메뉴얼에 작성해야함

모든 예외 클래스의 최상위 클래스는 Exception

예외 처리하기
try-catch 문
try-catch-finally 문
try-with-resources 문
트라이를 자동 해제 하도록 제공해주는 구문
close()를 명시적으로 호출하지 않아도 try{} 블록에서 열린 리소스는 정상적인 경우,
예외 발생한 경우 모두 해제됨.
해당 리소스가 AutoCloseable 인터페이스를 구현해야 함.
finally에 close()를 구현 안해도 리소스문을 선언하는 것 만으로도 해제됨.

package exception;

public class AutoCloseObj implements AutoCloseable {

	@Override
	public void close() throws Exception {
		System.out.println("리소스가 close() 되었습니다.");
	}
}

package exception;

public class AutoCloseTest {
	public static void main(String[] args) {
		// AutoCloseable 인터페이스 구현하기
		// (A a = new A(); B b = new B()) 세미 클론으로 여러개의 리소스문을 사용 가능
		// 자바 9부터는 AutoCloseObj obj = new AutoCloseObj()를 try 문 밖에 선언하여 참조 변수만 사용 가능
		AutoCloseObj obj = new AutoCloseObj();
		try (AutoCloseObj obj2 = obj) {
			// 강제 예외 발생
			throw new Exception();
		} catch(Exception e) {
			System.out.println("예외부분입니다.");
		}
	}
}

예외 처리 미루기
throws를 사용하여 예외처리 미루기
메서드 선언부에 throws를 추가
예외가 발생한 메서드에서 예외 처리를 하지 않고 이 메서드를 호출한 곳에서 예외 처리를 한다는 의미
main() 에서 throws를 사용하면 가상머신에서 처리 됨

package exception;

import java.io.FileInputStream;
import java.io.FileNotFoundException;

public class ThrowsException {
	public Class loadClass(String fileName, String className) throws
		FileNotFoundException, ClassNotFoundException { // 예외 처리 미루기 (호출할 때 예외 처리 하세요)
		FileInputStream fis = new FileInputStream(fileName);
		Class c = Class.forName(className); // Class 대문자는 동적으로 로딩하는 코드 동적 로딩 클래스
                                        // https://sujl95.tistory.com/74
		return c;
	}
	
	public static void main(String[] args) { // 에러 발생 예외 처리를 미뤘는데 예외 처리를 안함 
		// 메서드 호출할 때 예외를 처리함
		ThrowsException test = new ThrowsException();
		test.loadClass("a.txt", "java.lang.String");
	}
}

즉 메서드 선언부에 throws를 추가하면 예외처리가 미루어지며 메서드를 호출한 곳에서 예외 처리를 해야 함 
그런데 만약 main()에서 메서드를 호출한다면 throws를 메서드 선언부에 해주던가 try-catch문을 써야 하는데
main()에서 throws를 사용하면 또 미루어지는게 아니라 가상머신에서 자동으로 처리 함.

해결 방법
try/catch
add throws declaraion

사용자 정의 예외
JDK에서 제공되는 예외 클래스 외에 사용자가 필요에 의해 예외 클래스를 정의하여 사용 
기존 JDK 예외 클래스 중 가장 유사한 클래스에서 상속
기본적으로 Exception에서 상속해도 됨

package exception;

public class IDFormatException extends Exception {
	
	public IDFormatException(String message) {
		super(message);
	}
}


package exception;

public class IDFormatTest {
	// 멤버변수
	private String userID;
	
	public String getUserID() {
		return userID;
	}
	
	public void setUserID(String userID) throws IDFormatException {
		if (userID == null) {
			throw new IDFormatException("아이디는 null일 수 없습니다.");
		}
		else if (userID.length() < 8 || userID.length() > 20) {
			throw new IDFormatException("아이디는 최소 8자 이상이거나 20자 이하입니다.");
		}
		this.userID = userID;
	}
	
	
	public static void main(String[] args)  {
		IDFormatTest test = new IDFormatTest();
		
		String userID = null;
		try {
			test.setUserID(userID);
		} catch (IDFormatException e) {
			System.out.println(e.getMessage());
		}
		
		userID = "12346";
		try {
			test.setUserID(userID);
		} catch (IDFormatException e) {
			System.out.println(e.getMessage());
		}
		
	}
}
